Workbook

Sheet Summary
A1: SEASON 25-26
A2: Date | B2: Quantity | C2: Amount | D2: Category | E2: Type | F2: Club | G2: Details
A3: 45900 | B3: ='AUGUST 2025'!B38 -> 3 | C3: ='AUGUST 2025'!B40 -> 90 | D3: Hours | E3: Expected | F3: Blue Warriors
A4: 45930 | B4: ='SEPTEMBER 2025'!B37 -> 41.75 | C4: ='SEPTEMBER 2025'!B39 -> 1252.5 | D4: Hours | E4: Expected | F4: Blue Warriors
A5: 45961 | B5: ='OCTOBER 2025'!B37 -> 36.25 | C5: ='OCTOBER 2025'!B39 -> 1087.5 | D5: Hours | E5: Expected | F5: Blue Warriors
A6: 45991 | B6: ='NOVEMBER 2025'!B39 -> 30.5 | C6: ='NOVEMBER 2025'!B41 -> 915 | D6: Hours | E6: Expected | F6: Blue Warriors
A7: 46022 | B7: ='DECEMBER 2025'!B43 -> 8 | C7: ='DECEMBER 2025'!B45 -> 240 | D7: Hours | E7: Expected | F7: Blue Warriors
A8: 46053 | B8: ='JANUARY 2026'!B31 -> 0 | C8: ='JANUARY 2026'!B33 -> 0 | D8: Hours | E8: Expected | F8: Blue Warriors
A9: 46081 | B9: ='FEBRUARY 2026'!B31 -> 5.5 | C9: ='FEBRUARY 2026'!B33 -> 165 | D9: Hours | E9: Expected | F9: Blue Warriors
A10: 46112 | B10: ='MARCH 2026'!B39 -> 31.25 | C10: ='MARCH 2026'!B41 -> 937.5 | D10: Hours | E10: Expected | F10: Blue Warriors
A11: 46142 | B11: ='APRIL 2026'!B39 -> 21.5 | C11: ='APRIL 2026'!B41 -> 645 | D11: Hours | E11: Expected | F11: Blue Warriors
A12: 46173 | B12: ='MAY 2026'!B39 -> 43 | C12: ='MAY 2026'!B41 -> 1290 | D12: Hours | E12: Estimated | F12: Blue Warriors
A13: 46203 | B13: ='JUNE 2026'!B39 -> 43 | C13: ='JUNE 2026'!B41 -> 1290 | D13: Hours | E13: Estimated | F13: Blue Warriors
A14: 46234 | B14: ='JULY 2026'!B39 -> 0 | C14: ='JULY 2026'!B41 -> 0 | D14: Hours | E14: Estimated | F14: Blue Warriors
A15: Total | B15: =SUM(B3:B14) -> 263.75 | C15: =SUMIF(E3:E14,"Expected",C3:C14) -> 5332.5
A18: Paid
A19: Date | B19: BENEF. | C19: Amount | D19: Category | E19: Type | F19: Club | G19: Details
A20: 45967 | B20: Blue Warriors HOCKEY | C20: 2430 | D20: Hours | E20: Paid | F20: Blue Warriors | G20: Aug+Sept+Oct
A21: 45997 | B21: Blue Warriors HOCKEY | C21: 915 | D21: Hours | E21: Paid | F21: Blue Warriors | G21: Nov
C28: =SUM(C20:C26) -> 3345
A31: To Be Paid | C31: =C15-C28 -> 1987.5

Sheet JULY 2026
A1: Day | B1: 46085 | C1: 46087 | D1: 45973 | E1: 45975 | F1: 45973 | G1: 45975 | H1: 45973 | I1: 45975
A2: Time | B2: Wednesday | C2: Friday | D2: Wednesday | E2: Friday | F2: Wednesday | G2: Friday | H2: Wednesday | I2: Friday
A3: 13:00 - 13:15
A4: 13:15 - 13:30
A5: 13:30 - 13:45
A6: 13:45 - 14:00
A7: 14:00 - 14:15
A8: 14:15 - 14:30
A9: 14:30 - 14:45
A10: 14:45 - 15:00
A11: 15:00 - 15:15
A12: 15:15 - 15:30
A13: 15:30 - 15:45
A14: 15:45 - 16:00
... A34: 20:45 - 21:00
A35: Hours per Day | B35: =(COUNTA(B3:B32))/4 -> 0 | C35: =(COUNTA(C3:C32))/4 -> 0 | D35: =(COUNTA(D3:D32))/4 -> 0 | E35: =(COUNTA(E3:E32))/4 -> 0 | F35: =(COUNTA(F3:F32))/4 -> 0 | G35: =(COUNTA(G3:G32))/4 -> 0 | H35: =(COUNTA(H3:H32))/4 -> 0 | I35: =(COUNTA(I3:I32))/4 -> 0
A36: Hours per Week | B36: =B35+C35 -> 0 | D36: =E35+D35 -> 0 | F36: =G35+F35 -> 0 | H36: =I35+H35 -> 0
A37: WEEK | B37: 1 | D37: 2 | F37: 3 | H37: 4
A39: TOTAL Hours | B39: =SUM(B35:I35) -> 0
A40: VALUE per Hour | B40: 30
A41: Total | B41: =B39*B40 -> 0

Sheet JUNE 2026
A1: Day | B1: 46176 | C1: 46086 | D1: 46183 | E1: 46185 | F1: 46190 | G1: 46192 | H1: 46197 | I1: 46199
A2: Time | B2: Wednesday | C2: Friday | D2: Wednesday | E2: Friday | F2: Wednesday | G2: Friday | H2: Wednesday | I2: Friday
A3: 13:00 - 13:15
A4: 13:15 - 13:30
A5: 13:30 - 13:45 | B5: SUP. U8 | D5: SUP. U8 | F5: SUP. U8 | H5: SUP. U8
A6: 13:45 - 14:00 | B6: SUP. U8 | D6: SUP. U8 | F6: SUP. U8 | H6: SUP. U8
A7: 14:00 - 14:15 | B7: SUP. U8 | D7: SUP. U8 | F7: SUP. U8 | H7: SUP. U8
A8: 14:15 - 14:30 | B8: SUP. U8 | D8: SUP. U8 | F8: SUP. U8 | H8: SUP. U8
A9: 14:30 - 14:45 | B9: SUP. U8 | D9: SUP. U8 | F9: SUP. U8 | H9: SUP. U8
A10: 14:45 - 15:00 | B10: SUP. U8 | D10: SUP. U8 | F10: SUP. U8 | H10: SUP. U8
A11: 15:00 - 15:15 | B11: SUP. U8 | D11: SUP. U8 | F11: SUP. U8 | H11: SUP. U8
A12: 15:15 - 15:30 | B12: SUP. U8 | D12: SUP. U8 | F12: SUP. U8 | H12: SUP. U8
A13: 15:30 - 15:45 | B13: SUP. U8 | D13: SUP. U8 | F13: SUP. U8 | H13: SUP. U8
A14: 15:45 - 16:00 | B14: SUP | D14: SUP | F14: SUP | H14: SUP
A15: 16:00 - 16:15 | B15: SUP | D15: SUP | F15: SUP | H15: SUP
A16: 16:15 - 16:30 | B16: SUP | D16: SUP | F16: SUP | H16: SUP
A17: 16:30 - 16:45 | B17: SUP | C17: U9G1 | D17: SUP | E17: U9G1 | F17: SUP | G17: U9G1 | H17: SUP | I17: U9G1
A18: 16:45 - 17:00 | B18: SUP | C18: U9G1 | D18: SUP | E18: U9G1 | F18: SUP | G18: U9G1 | H18: SUP | I18: U9G1
A19: 17:00 - 17:15 | B19: SUP | C19: U9G1 | D19: SUP | E19: U9G1 | F19: SUP | G19: U9G1 | H19: SUP | I19: U9G1
A20: 17:15 - 17:30 | B20: SUP | C20: U9G1 | D20: SUP | E20: U9G1 | F20: SUP | G20: U9G1 | H20: SUP | I20: U9G1
A21: 17:30 - 17:45 | B21: SUP | C21: U9G1 | D21: SUP | E21: U9G1 | F21: SUP | G21: U9G1 | H21: SUP | I21: U9G1
A22: 17:45 - 18:00 | B22: SUP | C22: Sup. U11 | D22: SUP | E22: Sup. U11 | F22: SUP | G22: Sup. U11 | H22: SUP | I22: Sup. U11
A23: 18:00 - 18:15 | B23: SUP | C23: Sup. U11 | D23: SUP | E23: Sup. U11 | F23: SUP | G23: Sup. U11 | H23: SUP | I23: Sup. U11
A24: 18:15 - 18:30 | B24: SUP | C24: Sup. U11 | D24: SUP | E24: Sup. U11 | F24: SUP | G24: Sup. U11 | H24: SUP | I24: Sup. U11
A25: 18:30 - 18:45 | B25: SUP | C25: Sup. U11 | D25: SUP | E25: Sup. U11 | F25: SUP | G25: Sup. U11 | H25: SUP | I25: Sup. U11
A26: 18:45 - 19:00 | B26: SUP | C26: Sup. U11 | D26: SUP | E26: Sup. U11 | F26: SUP | G26: Sup. U11 | H26: SUP | I26: Sup. U11
A27: 19:00 - 19:15 | B27: U16G | C27: U16G | D27: U16G | E27: U16G | F27: U16G | G27: U16G | H27: U16G | I27: U16G
A28: 19:15 - 19:30 | B28: U16G | C28: U16G | D28: U16G | E28: U16G | F28: U16G | G28: U16G | H28: U16G | I28: U16G
... A31: 20:00 - 20:15 | B31: U16G | C31: U16G | D31: U16G | E31: U16G | F31: U16G | G31: U16G | H31: U16G | I31: U16G
A32: 20:15 - 20:30 | C32: U16G | E32: U16G | G32: U16G | I32: U16G
A33: 20:30 - 20:45
A34: 20:45 - 21:00
A35: Hours per Day | B35: =(COUNTA(B3:B32))/4 -> 6.75 | C35: =(COUNTA(C3:C32))/4 -> 4 | D35: =(COUNTA(D3:D32))/4 -> 6.75 | E35: =(COUNTA(E3:E32))/4 -> 4 | F35: =(COUNTA(F3:F32))/4 -> 6.75 | G35: =(COUNTA(G3:G32))/4 -> 4 | H35: =(COUNTA(H3:H32))/4 -> 6.75 | I35: =(COUNTA(I3:I32))/4 -> 4
A36: Hours per Week | B36: =B35+C35 -> 10.75 | D36: =E35+D35 -> 10.75 | F36: =G35+F35 -> 10.75 | H36: =I35+H35 -> 10.75
A37: WEEK | B37: 1 | D37: 2 | F37: 3 | H37: 4
A39: TOTAL Hours | B39: =SUM(B35:I35) -> 43
A40: VALUE per Hour | B40: 30
A41: Total | B41: =B39*B40 -> 1290

Sheet MAY 2026
A1: Day | B1: 46148 | C1: 46150 | D1: 46155 | E1: 46157 | F1: 46162 | G1: 46164 | H1: 46169 | I1: 46171
A2: Time | B2: Wednesday | C2: Friday | D2: Wednesday | E2: Friday | F2: Wednesday | G2: Friday | H2: Wednesday | I2: Friday
A3: 13:00 - 13:15
A4: 13:15 - 13:30
A5: 13:30 - 13:45 | B5: SUP. U8 | D5: SUP. U8 | F5: SUP. U8 | H5: SUP. U8
A6: 13:45 - 14:00 | B6: SUP. U8 | D6: SUP. U8 | F6: SUP. U8 | H6: SUP. U8
A7: 14:00 - 14:15 | B7: SUP. U8 | D7: SUP. U8 | F7: SUP. U8 | H7: SUP. U8
A8: 14:15 - 14:30 | B8: SUP. U8 | D8: SUP. U8 | F8: SUP. U8 | H8: SUP. U8
A9: 14:30 - 14:45 | B9: SUP. U8 | D9: SUP. U8 | F9: SUP. U8 | H9: SUP. U8
A10: 14:45 - 15:00 | B10: SUP. U8 | D10: SUP. U8 | F10: SUP. U8 | H10: SUP. U8
A11: 15:00 - 15:15 | B11: SUP. U8 | D11: SUP. U8 | F11: SUP. U8 | H11: SUP. U8
A12: 15:15 - 15:30 | B12: SUP. U8 | D12: SUP. U8 | F12: SUP. U8 | H12: SUP. U8
A13: 15:30 - 15:45 | B13: SUP. U8 | D13: SUP. U8 | F13: SUP. U8 | H13: SUP. U8
A14: 15:45 - 16:00 | B14: SUP | D14: SUP | F14: SUP | H14: SUP
A15: 16:00 - 16:15 | B15: SUP | D15: SUP | F15: SUP | H15: SUP
A16: 16:15 - 16:30 | B16: SUP | D16: SUP | F16: SUP | H16: SUP
A17: 16:30 - 16:45 | B17: SUP | C17: U9G1 | D17: SUP | E17: U9G1 | F17: SUP | G17: U9G1 | H17: SUP | I17: U9G1
A18: 16:45 - 17:00 | B18: SUP | C18: U9G1 | D18: SUP | E18: U9G1 | F18: SUP | G18: U9G1 | H18: SUP | I18: U9G1
A19: 17:00 - 17:15 | B19: SUP | C19: U9G1 | D19: SUP | E19: U9G1 | F19: SUP | G19: U9G1 | H19: SUP | I19: U9G1
A20: 17:15 - 17:30 | B20: SUP | C20: U9G1 | D20: SUP | E20: U9G1 | F20: SUP | G20: U9G1 | H20: SUP | I20: U9G1
A21: 17:30 - 17:45 | B21: SUP | C21: U9G1 | D21: SUP | E21: U9G1 | F21: SUP | G21: U9G1 | H21: SUP | I21: U9G1
A22: 17:45 - 18:00 | B22: SUP | C22: Sup. U11 | D22: SUP | E22: Sup. U11 | F22: SUP | G22: Sup. U11 | H22: SUP | I22: Sup. U11
A23: 18:00 - 18:15 | B23: SUP | C23: Sup. U11 | D23: SUP | E23: Sup. U11 | F23: SUP | G23: Sup. U11 | H23: SUP | I23: Sup. U11
A24: 18:15 - 18:30 | B24: SUP | C24: Sup. U11 | D24: SUP | E24: Sup. U11 | F24: SUP | G24: Sup. U11 | H24: SUP | I24: Sup. U11
A25: 18:30 - 18:45 | B25: SUP | C25: Sup. U11 | D25: SUP | E25: Sup. U11 | F25: SUP | G25: Sup. U11 | H25: SUP | I25: Sup. U11
A26: 18:45 - 19:00 | B26: SUP | C26: Sup. U11 | D26: SUP | E26: Sup. U11 | F26: SUP | G26: Sup. U11 | H26: SUP | I26: Sup. U11
A27: 19:00 - 19:15 | B27: U16G | C27: U16G | D27: U16G | E27: U16G | F27: U16G | G27: U16G | H27: U16G | I27: U16G
A28: 19:15 - 19:30 | B28: U16G | C28: U16G | D28: U16G | E28: U16G | F28: U16G | G28: U16G | H28: U16G | I28: U16G
... A31: 20:00 - 20:15 | B31: U16G | C31: U16G | D31: U16G | E31: U16G | F31: U16G | G31: U16G | H31: U16G | I31: U16G
A32: 20:15 - 20:30 | C32: U16G | E32: U16G | G32: U16G | I32: U16G
A33: 20:30 - 20:45
A34: 20:45 - 21:00
A35: Hours per Day | B35: =(COUNTA(B3:B32))/4 -> 6.75 | C35: =(COUNTA(C3:C32))/4 -> 4 | D35: =(COUNTA(D3:D32))/4 -> 6.75 | E35: =(COUNTA(E3:E32))/4 -> 4 | F35: =(COUNTA(F3:F32))/4 -> 6.75 | G35: =(COUNTA(G3:G32))/4 -> 4 | H35: =(COUNTA(H3:H32))/4 -> 6.75 | I35: =(COUNTA(I3:I32))/4 -> 4
A36: Hours per Week | B36: =B35+C35 -> 10.75 | D36: =E35+D35 -> 10.75 | F36: =G35+F35 -> 10.75 | H36: =I35+H35 -> 10.75
A37: WEEK | B37: 1 | D37: 2 | F37: 3 | H37: 4
A39: TOTAL Hours | B39: =SUM(B35:I35) -> 43
A40: VALUE per Hour | B40: 30
A41: Total | B41: =B39*B40 -> 1290

Sheet APRIL 2026
A1: Day | B1: 46130 | C1: 46132 | D1: 46137 | E1: 46139
A2: Time | B2: Wednesday | C2: Friday | D2: Wednesday | E2: Friday
A3: 13:00 - 13:15
A4: 13:15 - 13:30
A5: 13:30 - 13:45 | B5: SUP. U8 | D5: SUP. U8
A6: 13:45 - 14:00 | B6: SUP. U8 | D6: SUP. U8
A7: 14:00 - 14:15 | B7: SUP. U8 | D7: SUP. U8
A8: 14:15 - 14:30 | B8: SUP. U8 | D8: SUP. U8
A9: 14:30 - 14:45 | B9: SUP. U8 | D9: SUP. U8
A10: 14:45 - 15:00 | B10: SUP. U8 | D10: SUP. U8
A11: 15:00 - 15:15 | B11: SUP. U8 | D11: SUP. U8
A12: 15:15 - 15:30 | B12: SUP. U8 | D12: SUP. U8
A13: 15:30 - 15:45 | B13: SUP. U8 | D13: SUP. U8
A14: 15:45 - 16:00 | B14: SUP | D14: SUP
A15: 16:00 - 16:15 | B15: SUP | D15: SUP
A16: 16:15 - 16:30 | B16: SUP | D16: SUP
A17: 16:30 - 16:45 | B17: SUP | C17: U9G1 | D17: SUP | E17: U9G1
A18: 16:45 - 17:00 | B18: SUP | C18: U9G1 | D18: SUP | E18: U9G1
A19: 17:00 - 17:15 | B19: SUP | C19: U9G1 | D19: SUP | E19: U9G1
A20: 17:15 - 17:30 | B20: SUP | C20: U9G1 | D20: SUP | E20: U9G1
A21: 17:30 - 17:45 | B21: SUP | C21: U9G1 | D21: SUP | E21: U9G1
A22: 17:45 - 18:00 | B22: SUP | C22: Sup. U11 | D22: SUP | E22: Sup. U11
A23: 18:00 - 18:15 | B23: SUP | C23: Sup. U11 | D23: SUP | E23: Sup. U11
A24: 18:15 - 18:30 | B24: SUP | C24: Sup. U11 | D24: SUP | E24: Sup. U11
A25: 18:30 - 18:45 | B25: SUP | C25: Sup. U11 | D25: SUP | E25: Sup. U11
A26: 18:45 - 19:00 | B26: SUP | C26: Sup. U11 | D26: SUP | E26: Sup. U11
A27: 19:00 - 19:15 | B27: U16G | C27: U16G | D27: U16G | E27: U16G
A28: 19:15 - 19:30 | B28: U16G | C28: U16G | D28: U16G | E28: U16G
... A31: 20:00 - 20:15 | B31: U16G | C31: U16G | D31: U16G | E31: U16G
A32: 20:15 - 20:30 | C32: U16G | E32: U16G
A33: 20:30 - 20:45
A34: 20:45 - 21:00
A35: Hours per Day | B35: =(COUNTA(B3:B32))/4 -> 6.75 | C35: =(COUNTA(C3:C32))/4 -> 4 | D35: =(COUNTA(D3:D32))/4 -> 6.75 | E35: =(COUNTA(E3:E32))/4 -> 4
A36: Hours per Week | B36: =C35+B35 -> 10.75 | D36: =E35+D35 -> 10.75
A37: WEEK | B37: 3 | D37: 4
A39: TOTAL Hours | B39: =SUM(B35:E35) -> 21.5
A40: VALUE per Hour | B40: 30
A41: Total | B41: =B39*B40 -> 645

Sheet MARCH 2026
A1: Day | B1: 46085 | C1: 46087 | D1: 46092 | E1: 46094 | F1: 46099 | G1: 46101 | H1: 46106 | I1: 46108
A2: Time | B2: Wednesday | C2: Friday | D2: Wednesday | E2: Friday | F2: Wednesday | G2: Friday | H2: Wednesday | I2: Friday
A3: 13:00 - 13:15
A4: 13:15 - 13:30
A5: 13:30 - 13:45 | B5: SUP. U8 | D5: SUP. U8 | F5: SUP. U8 | H5: SUP. U8
A6: 13:45 - 14:00 | B6: SUP. U8 | D6: SUP. U8 | F6: SUP. U8 | H6: SUP. U8
A7: 14:00 - 14:15 | B7: SUP. U8 | D7: SUP. U8 | F7: SUP. U8 | H7: SUP. U8
A8: 14:15 - 14:30 | B8: SUP. U8 | D8: SUP. U8 | F8: SUP. U8 | H8: SUP. U8
A9: 14:30 - 14:45 | B9: SUP. U8 | D9: SUP. U8 | F9: SUP. U8 | H9: SUP. U8
A10: 14:45 - 15:00 | B10: SUP. U8 | D10: SUP. U8 | F10: SUP. U8 | H10: SUP. U8
A11: 15:00 - 15:15 | B11: SUP. U8 | D11: SUP. U8 | F11: SUP. U8 | H11: SUP. U8
A12: 15:15 - 15:30 | B12: SUP. U8 | D12: SUP. U8 | F12: SUP. U8 | H12: SUP. U8
A13: 15:30 - 15:45 | B13: SUP. U8 | D13: SUP. U8 | F13: SUP. U8 | H13: SUP. U8
A14: 15:45 - 16:00 | B14: U14B1 | H14: SUP
A15: 16:00 - 16:15 | B15: U14B1 | H15: SUP
A16: 16:15 - 16:30 | H16: SUP
A17: 16:30 - 16:45 | C17: U9G1 | E17: U9G1 | G17: U9G1 | H17: SUP | I17: U9G1
A18: 16:45 - 17:00 | C18: U9G1 | E18: U9G1 | G18: U9G1 | H18: SUP | I18: U9G1
A19: 17:00 - 17:15 | C19: U9G1 | E19: U9G1 | G19: U9G1 | H19: SUP | I19: U9G1
A20: 17:15 - 17:30 | C20: U9G1 | E20: U9G1 | G20: U9G1 | H20: SUP | I20: U9G1
A21: 17:30 - 17:45 | C21: U9G1 | E21: U9G1 | G21: U9G1 | H21: SUP | I21: U9G1
A22: 17:45 - 18:00 | C22: Sup. U11 | E22: Sup. U11 | G22: Sup. U11 | H22: SUP | I22: Sup. U11
A23: 18:00 - 18:15 | C23: Sup. U11 | E23: Sup. U11 | G23: Sup. U11 | H23: SUP | I23: Sup. U11
A24: 18:15 - 18:30 | C24: Sup. U11 | E24: Sup. U11 | G24: Sup. U11 | H24: SUP | I24: Sup. U11
A25: 18:30 - 18:45 | C25: Sup. U11 | E25: Sup. U11 | G25: Sup. U11 | H25: SUP | I25: Sup. U11
A26: 18:45 - 19:00 | C26: Sup. U11 | E26: Sup. U11 | G26: Sup. U11 | H26: SUP | I26: Sup. U11
A27: 19:00 - 19:15 | C27: U16G | E27: U16G | F27: U16G | G27: U16G | H27: U16G | I27: U16G
A28: 19:15 - 19:30 | C28: U16G | E28: U16G | F28: U16G | G28: U16G | H28: U16G | I28: U16G
A29: 19:30 - 19:45 | C29: U16G | E29: U16G | F29: U16G | G29: U16G | H29: U16G | I29: U16G
A30: 19:45 - 20:00 | C30: U16G | E30: U16G | F30: U16G | G30: U16G | H30: U16G | I30: U16G
A31: 20:00 - 20:15 | C31: U16G | E31: U16G | F31: U16G | G31: U16G | H31: U16G | I31: U16G
A32: 20:15 - 20:30 | C32: U16G | E32: U16G | G32: U16G | I32: U16G
A33: 20:30 - 20:45
A34: 20:45 - 21:00
A35: Hours per Day | B35: =(COUNTA(B3:B32))/4 -> 2.75 | C35: =(COUNTA(C3:C32))/4 -> 4 | D35: =(COUNTA(D3:D32))/4 -> 2.25 | E35: =(COUNTA(E3:E32))/4 -> 4 | F35: =(COUNTA(F3:F32))/4 -> 3.5 | G35: =(COUNTA(G3:G32))/4 -> 4 | H35: =(COUNTA(H3:H32))/4 -> 6.75 | I35: =(COUNTA(I3:I32))/4 -> 4
A36: Hours per Week | B36: =B35+C35 -> 6.75 | D36: =E35+D35 -> 6.25 | F36: =G35+F35 -> 7.5 | H36: =I35+H35 -> 10.75
A37: WEEK | B37: 1 | D37: 2 | F37: 3 | H37: 4
A39: TOTAL Hours | B39: =SUM(B35:I35) -> 31.25
A40: VALUE per Hour | B40: 30
A41: Total | B41: =B39*B40 -> 937.5

Sheet FEBRUARY 2026
A1: Day | B1: 45992 | C1: 45994
A2: Time | B2: Wednesday | C2: Friday
A3: 13:00 - 13:15
A4: 13:15 - 13:30
A5: 13:30 - 13:45 | B5: U7G
A6: 13:45 - 14:00 | B6: U7G
A7: 14:00 - 14:15 | B7: U7G
A8: 14:15 - 14:30 | B8: U7G
A9: 14:30 - 14:45 | B9: U7G
A10: 14:45 - 15:00 | B10: U7G
A11: 15:00 - 15:15 | B11: U7B
A12: 15:15 - 15:30 | B12: U7B
A13: 15:30 - 15:45 | B13: U7B
A14: 15:45 - 16:00 | B14: U7B
A15: 16:00 - 16:15 | B15: U7B
A16: 16:15 - 16:30 | B16: U7B
A17: 16:30 - 16:45 | C17: U9G1
A18: 16:45 - 17:00 | C18: U9G1
A19: 17:00 - 17:15 | C19: U9G1
A20: 17:15 - 17:30 | C20: U9G1
A21: 17:30 - 17:45 | C21: U9G1
A22: 17:45 - 18:00 | C22: U9G1
A23: 18:00 - 18:15 | C23: Sup
A24: 18:15 - 18:30 | C24: Sup
A25: 18:30 - 18:45 | C25: Sup
A26: 18:45 - 19:00 | C26: Sup
A27: Hours per Day | B27: =(COUNTA(B3:B26))/4 -> 3 | C27: =(COUNTA(C3:C26))/4 -> 2.5
A28: Hours per Week | B28: =B27+C27 -> 5.5
A29: WEEK | B29: 1
A31: TOTAL Hours | B31: =SUM(B27:C27) -> 5.5
A32: VALUE per Hour | B32: 30
A33: Total | B33: =B31*B32 -> 165

Sheet JANUARY 2026
A1: Day
A2: Time
A3: 13:00 - 13:15
A4: 13:15 - 13:30
A5: 13:30 - 13:45
A6: 13:45 - 14:00
A7: 14:00 - 14:15
A8: 14:15 - 14:30
A9: 14:30 - 14:45
A10: 14:45 - 15:00
A11: 15:00 - 15:15
A12: 15:15 - 15:30
... A29: WEEK
A31: TOTAL Hours | B31: =SUM(B27) -> 0
A32: VALUE per Hour | B32: 30
A33: Total | B33: =B31*B32 -> 0

Sheet DECEMBER 2025
A1: Day | B1: 45992 | C1: 45994 | D1: 45999
A2: Time | B2: Monday - Indoor | C2: Wednesday - Indoor | D2: Monday - Indoor
A3: 13:00 - 13:15
A4: 13:15 - 13:30
A5: 13:30 - 13:45
A6: 13:45 - 14:00
A7: 14:00 - 14:15
A8: 14:15 - 14:30
A9: 14:30 - 14:45 | C9: U9G1
A10: 14:45 - 15:00 | C10: U9G1
A11: 15:00 - 15:15 | C11: U9G1
A12: 15:15 - 15:30 | C12: U9G1
A13: 15:30 - 15:45 | C13: U9G1
A14: 15:45 - 16:00 | C14: U9G1
A15: 16:00 - 16:15 | C15: U11G1
A16: 16:15 - 16:30 | C16: U11G1
A17: 16:30 - 16:45 | C17: U11G1
A18: 16:45 - 17:00 | C18: U11G1
A19: 17:00 - 17:15 | C19: U11G1
A20: 17:15 - 17:30 | C20: U11G1
A21: 17:30 - 17:45
A22: 17:45 - 18:00
A23: 18:00 - 18:15
A24: 18:15 - 18:30 | B24: U14G1 | D24: U14G1
A25: 18:30 - 18:45 | B25: U14G1 | D25: U14G1
A26: 18:45 - 19:00 | B26: U14G1 | D26: U14G1
A27: 19:00 - 19:15 | B27: U14G1 | D27: U14G1
A28: 19:15 - 19:30 | B28: U14G1 | D28: U14G1
A29: 19:30 - 19:45
A30: 19:45 - 20:00
A31: 20:00 - 20:15 | B31: Trimmers | D31: Trimmers
A32: 20:15 - 20:30 | B32: Trimmers | D32: Trimmers
A33: 20:30 - 20:45 | B33: Trimmers | D33: Trimmers
A34: 20:45 - 21:00 | B34: Trimmers | D34: Trimmers
A35: 21:00 - 21:15 | B35: Trimmers | D35: Trimmers
A36: 21:15 - 21:30 | B36: Trimmers | D36: Trimmers
A37: 21:30 - 21:45 | B37: Trimmers | D37: Trimmers
A38: 21:45 - 22:00 | B38: Trimmers | D38: Trimmers
A39: Hours per Day | B39: =(COUNTA(B3:B38))/4 -> 3.25 | C39: =(COUNTA(C3:C32))/4 -> 3 | D39: =(COUNTA(D3:D32))/4 -> 1.75
A40: Hours per Week | B40: =B39+C39 -> 6.25 | D40: =D39 -> 1.75
...

Sheet NOVEMBER 2025
A1: Day | B1: 45966 | C1: 45968 | D1: 45973 | E1: 45975 | F1: 45980 | G1: 45988
A2: Time | B2: Wednesday | C2: Friday | D2: Wednesday | E2: Friday | F2: Wednesday | G2: Thursday - Indoor
A3: 13:00 - 13:15
A4: 13:15 - 13:30
A5: 13:30 - 13:45 | B5: SUP. U8 | D5: SUP. U8 | F5: SUP. U8
A6: 13:45 - 14:00 | B6: SUP. U8 | D6: SUP. U8 | F6: SUP. U8
A7: 14:00 - 14:15 | B7: SUP. U8 | D7: SUP. U8 | F7: SUP. U8
A8: 14:15 - 14:30 | B8: SUP. U8 | D8: SUP. U8 | F8: SUP. U8
A9: 14:30 - 14:45 | B9: SUP. U8 | D9: SUP. U8 | F9: SUP. U8
A10: 14:45 - 15:00 | B10: SUP. U9 | D10: SUP. U9 | F10: SUP. U9
A11: 15:00 - 15:15 | B11: SUP. U9 | D11: SUP. U9 | F11: SUP. U9
A12: 15:15 - 15:30 | B12: SUP. U9 | D12: SUP. U9 | F12: SUP. U9
A13: 15:30 - 15:45 | B13: SUP. U9 | D13: SUP. U9 | F13: SUP. U9
A14: 15:45 - 16:00 | B14: U11B1 | D14: U11B1
A15: 16:00 - 16:15 | B15: U11B1 | D15: U11B1
A16: 16:15 - 16:30 | B16: U11B1 | D16: U11B1
A17: 16:30 - 16:45 | B17: U11B1 | C17: U9G2 | D17: U11B1 | E17: U9G2
A18: 16:45 - 17:00 | B18: U11B1 | C18: U9G2 | D18: U11B1 | E18: U9G2
A19: 17:00 - 17:15 | B19: U14B2 | C19: U9G2 | D19: U14B2 | E19: U9G2 | F19: U14B1
A20: 17:15 - 17:30 | B20: U14B2 | C20: U9G2 | D20: U14B2 | E20: U9G2 | F20: U14B1
A21: 17:30 - 17:45 | B21: U14B2 | C21: U9G2 | D21: U14B2 | E21: U9G2 | F21: U14B1 | G21: U19G2/G3
A22: 17:45 - 18:00 | B22: U14B2 | C22: Sup. U11 | D22: U14B2 | E22: Sup. U11 | F22: U14B1 | G22: U19G2/G3
A23: 18:00 - 18:15 | B23: U14B2 | C23: Sup. U11 | D23: U14B2 | E23: Sup. U11 | F23: U14B1 | G23: U19G2/G3
A24: 18:15 - 18:30 | B24: U14B2 | C24: Sup. U11 | D24: U14B2 | E24: Sup. U11 | F24: U14B1 | G24: U19G2/G3
A25: 18:30 - 18:45 | B25: U16G | C25: Sup. U11 | D25: U16G | E25: Sup. U11 | F25: U16G | G25: U19G2/G3
A26: 18:45 - 19:00 | B26: U16G | C26: Sup. U11 | D26: U16G | E26: Sup. U11 | F26: U16G | G26: U19G1
A27: 19:00 - 19:15 | B27: U16G | C27: U16G | D27: U16G | E27: U16G | F27: U16G | G27: U19G1
A28: 19:15 - 19:30 | B28: U16G | C28: U16G | D28: U16G | E28: U16G | F28: U16G | G28: U19G1
A29: 19:30 - 19:45 | B29: U16G | C29: U16G | D29: U16G | E29: U16G | F29: U16G | G29: U19G1
A30: 19:45 - 20:00 | B30: U16G | C30: U16G | D30: U16G | E30: U16G | F30: U16G | G30: U19G1
A31: 20:00 - 20:15 | B31: U16G | C31: U16G | D31: U16G | E31: U16G | F31: U16G | G31: U19G1
A32: 20:15 - 20:30 | C32: U16G | E32: U16G | G32: GK
A33: 20:30 - 20:45 | G33: GK
A34: 20:45 - 21:00 | G34: GK
A35: Hours per Day | B35: =(COUNTA(B3:B32))/4 -> 6.75 | C35: =(COUNTA(C3:C32))/4 -> 4 | D35: =(COUNTA(D3:D32))/4 -> 6.75 | E35: =(COUNTA(E3:E32))/4 -> 4 | F35: =(COUNTA(F3:F32))/4 -> 5.5 | G35: =(COUNTA(G3:G34))/4 -> 3.5
A36: Hours per Week | B36: =B35+C35 -> 10.75 | D36: =E35+D35 -> 10.75 | F36: =F35 -> 5.5 | G36: =G35 -> 3.5
A37: WEEK | B37: 1 | D37: 2 | F37: 3 | G37: 3
A39: TOTAL Hours | B39: =SUM(B35:G35) -> 30.5
A40: VALUE per Hour | B40: 30
A41: Total | B41: =B39*B40 -> 915

Sheet OCTOBER 2025
A1: Day | B1: 45931 | C1: 45933 | D1: 45938 | E1: 45940 | F1: 45944 | G1: 45947 | H1: 45954
A2: Time | B2: Wednesday | C2: Friday | D2: Wednesday | E2: Friday | F2: Wednesday | G2: Friday | H2: Friday
A3: 13:00 - 13:15
A4: 13:15 - 13:30
A5: 13:30 - 13:45 | B5: SUP. U8 | D5: SUP. U8 | F5: SUP. U8
A6: 13:45 - 14:00 | B6: SUP. U8 | D6: SUP. U8 | F6: SUP. U8
A7: 14:00 - 14:15 | B7: SUP. U8 | D7: SUP. U8 | F7: SUP. U8
A8: 14:15 - 14:30 | B8: SUP. U8 | D8: SUP. U8 | F8: SUP. U8
A9: 14:30 - 14:45 | B9: SUP. U8 | D9: SUP. U8 | F9: SUP. U8
A10: 14:45 - 15:00 | B10: SUP. U9 | D10: SUP. U9 | F10: SUP. U9
A11: 15:00 - 15:15 | B11: SUP. U9 | D11: SUP. U9 | F11: SUP. U9
A12: 15:15 - 15:30 | B12: SUP. U9 | D12: SUP. U9 | F12: SUP. U9
A13: 15:30 - 15:45 | B13: SUP. U9 | D13: SUP. U9 | F13: SUP. U9
A14: 15:45 - 16:00 | B14: U11B1 | D14: U11B1 | F14: U11B1
A15: 16:00 - 16:15 | B15: U11B1 | D15: U11B1 | F15: U11B1
A16: 16:15 - 16:30 | B16: U11B1 | D16: U11B1 | F16: U11B1
A17: 16:30 - 16:45 | B17: U11B1 | C17: U9G2 | D17: U11B1 | E17: U9G2 | F17: U11B1 | G17: U9G2 | H17: U9G2
A18: 16:45 - 17:00 | B18: U11B1 | C18: U9G2 | D18: U11B1 | E18: U9G2 | F18: U11B1 | G18: U9G2 | H18: U9G2
A19: 17:00 - 17:15 | B19: U14B2 | C19: U9G2 | D19: U14B2 | E19: U9G2 | F19: U14B2 | G19: U9G2 | H19: U9G2
A20: 17:15 - 17:30 | B20: U14B2 | C20: U9G2 | D20: U14B2 | E20: U9G2 | F20: U14B2 | G20: U9G2 | H20: U9G2
A21: 17:30 - 17:45 | B21: U14B2 | C21: U9G2 | D21: U14B2 | E21: U9G2 | F21: U14B2 | G21: U9G2 | H21: U9G2
A22: 17:45 - 18:00 | B22: U14B2 | C22: Sup. U11 | D22: U14B2 | E22: Sup. U11 | F22: U14B2 | G22: Sup. U11 | H22: Sup. U11
A23: 18:00 - 18:15 | B23: U14B2 | C23: Sup. U11 | D23: U14B2 | E23: Sup. U11 | F23: U14B2 | G23: Sup. U11 | H23: Sup. U11
A24: 18:15 - 18:30 | B24: U14B2 | C24: Sup. U11 | D24: U14B2 | E24: Sup. U11 | F24: U14B2 | G24: Sup. U11 | H24: Sup. U11
A25: 18:30 - 18:45 | B25: U16G | C25: Sup. U11 | D25: U16G | E25: Sup. U11 | F25: U16G | G25: Sup. U11 | H25: Sup. U11
A26: 18:45 - 19:00 | B26: U16G | C26: Sup. U11 | D26: U16G | E26: Sup. U11 | F26: U16G | G26: Sup. U11 | H26: Sup. U11
A27: 19:00 - 19:15 | B27: U16G | C27: U16G | D27: U16G | E27: U16G | F27: U16G | G27: U16G | H27: U16G
A28: 19:15 - 19:30 | B28: U16G | C28: U16G | D28: U16G | E28: U16G | F28: U16G | G28: U16G | H28: U16G
... A31: 20:00 - 20:15 | B31: U16G | C31: U16G | D31: U16G | E31: U16G | F31: U16G | G31: U16G | H31: U16G
A32: 20:15 - 20:30 | C32: U16G | E32: U16G | G32: U16G | H32: U16G
A33: Hours per Day | B33: =(COUNTA(B3:B32))/4 -> 6.75 | C33: =(COUNTA(C3:C32))/4 -> 4 | D33: =(COUNTA(D3:D32))/4 -> 6.75 | E33: =(COUNTA(E3:E32))/4 -> 4 | F33: =(COUNTA(F3:F32))/4 -> 6.75 | G33: =(COUNTA(G3:G32))/4 -> 4 | H33: =(COUNTA(H3:H32))/4 -> 4
A34: Hours per Week | B34: =B33+C33 -> 10.75 | D34: =E33+D33 -> 10.75 | F34: =G33+F33 -> 10.75 | H34: =SUM(H33) -> 4
A35: WEEK | B35: 1 | D35: 2 | F35: 3 | H35: 4
A37: TOTAL Hours | B37: =SUM(B33:H33) -> 36.25
A38: VALUE per Hour | B38: 30
A39: Total | B39: =B37*B38 -> 1087.5

Sheet SEPTEMBER 2025
A1: Day | B1: 45903 | C1: 45905 | D1: 45910 | E1: 45912 | F1: 45917 | G1: 45919 | H1: 45924 | I1: 45926
A2: Time | B2: Wednesday | C2: Friday | D2: Wednesday | E2: Friday | F2: Wednesday | G2: Friday | H2: Wednesday | I2: Friday
A3: 13:00 - 13:15 | B3: SUP. U8
A4: 13:15 - 13:30 | B4: SUP. U8
A5: 13:30 - 13:45 | B5: SUP. U8 | D5: SUP. U8 | F5: SUP. U8 | H5: SUP. U8
A6: 13:45 - 14:00 | B6: SUP. U8 | D6: SUP. U8 | F6: SUP. U8 | H6: SUP. U8
A7: 14:00 - 14:15 | B7: SUP. U8 | D7: SUP. U8 | F7: SUP. U8 | H7: SUP. U8
A8: 14:15 - 14:30 | B8: SUP. U8 | D8: SUP. U8 | F8: SUP. U8 | H8: SUP. U8
A9: 14:30 - 14:45 | B9: SUP. U8 | D9: SUP. U8 | F9: SUP. U8 | H9: SUP. U8
A10: 14:45 - 15:00 | B10: SUP. U9 | D10: SUP. U9 | F10: SUP. U9 | H10: SUP. U9
A11: 15:00 - 15:15 | B11: SUP. U9 | D11: SUP. U9 | F11: SUP. U9 | H11: SUP. U9
A12: 15:15 - 15:30 | B12: SUP. U9 | D12: SUP. U9 | F12: SUP. U9 | H12: SUP. U9
A13: 15:30 - 15:45 | B13: SUP. U9 | D13: SUP. U9 | F13: SUP. U9 | H13: SUP. U9
A14: 15:45 - 16:00 | B14: U11B1 | D14: U11B1 | F14: U11B1 | H14: U11B1
A15: 16:00 - 16:15 | B15: U11B1 | D15: U11B1 | F15: U11B1 | H15: U11B1
A16: 16:15 - 16:30 | B16: U11B1 | D16: U11B1 | F16: U11B1 | H16: U11B1
A17: 16:30 - 16:45 | B17: U11B1 | C17: U9B1 | D17: U11B1 | E17: U9G2 | F17: U11B1 | G17: U9G2 | H17: U11B1 | I17: U9G2
A18: 16:45 - 17:00 | B18: U11B1 | C18: U9B1 | D18: U11B1 | E18: U9G2 | F18: U11B1 | G18: U9G2 | H18: U11B1 | I18: U9G2
A19: 17:00 - 17:15 | B19: U14B2 | C19: U9B1 | D19: U14B2 | E19: U9G2 | F19: U14B2 | G19: U9G2 | H19: U14B2 | I19: U9G2
A20: 17:15 - 17:30 | B20: U14B2 | C20: U9B1 | D20: U14B2 | E20: U9G2 | F20: U14B2 | G20: U9G2 | H20: U14B2 | I20: U9G2
A21: 17:30 - 17:45 | B21: U14B2 | C21: U9B1 | D21: U14B2 | E21: U9G2 | F21: U14B2 | G21: U9G2 | H21: U14B2 | I21: U9G2
A22: 17:45 - 18:00 | B22: U14B2 | C22: U11B1 | D22: U14B2 | E22: U11B2 | F22: U14B2 | G22: Sup. U11 | H22: U14B2 | I22: Sup. U11
A23: 18:00 - 18:15 | B23: U14B2 | C23: U11B1 | D23: U14B2 | E23: U11B2 | F23: U14B2 | G23: Sup. U11 | H23: U14B2 | I23: Sup. U11
A24: 18:15 - 18:30 | B24: U14B2 | C24: U11B1 | D24: U14B2 | E24: U11B2 | F24: U14B2 | G24: Sup. U11 | H24: U14B2 | I24: Sup. U11
A25: 18:30 - 18:45 | C25: U11B1 | D25: U16G | E25: U11B2 | F25: U16G | G25: Sup. U11 | H25: U16G | I25: Sup. U11
A26: 18:45 - 19:00 | C26: U11B1 | D26: U16G | E26: U11B2 | F26: U16G | G26: Sup. U11 | H26: U16G | I26: Sup. U11
A27: 19:00 - 19:15 | C27: U16G2 | D27: U16G | E27: U16G | F27: U16G | G27: U16G | H27: U16G | I27: U16G
A28: 19:15 - 19:30 | C28: U16G2 | D28: U16G | E28: U16G | F28: U16G | G28: U16G | H28: U16G | I28: U16G
A29: 19:30 - 19:45 | C29: U16G2 | D29: U16G | E29: U16G | F29: U16G | G29: U16G | H29: U16G | I29: U16G
A30: 19:45 - 20:00 | C30: U16G2 | D30: U16G | E30: U16G | F30: U16G | G30: U16G | H30: U16G | I30: U16G
A31: 20:00 - 20:15 | C31: U16G2 | D31: U16G | E31: U16G | F31: U16G | G31: U16G | H31: U16G | I31: U16G
A32: 20:15 - 20:30 | C32: U16G2 | E32: U16G | G32: U16G | I32: U16G
A33: Hours per Day | B33: =(COUNTA(B3:B32))/4 -> 5.5 | C33: =(COUNTA(C3:C32))/4 -> 4 | D33: =(COUNTA(D3:D32))/4 -> 6.75 | E33: =(COUNTA(E3:E32))/4 -> 4 | F33: =(COUNTA(F3:F32))/4 -> 6.75 | G33: =(COUNTA(G3:G32))/4 -> 4 | H33: =(COUNTA(H3:H32))/4 -> 6.75 | I33: =(COUNTA(I3:I32))/4 -> 4
A34: Hours per Week | B34: =B33+C33 -> 9.5 | D34: =E33+D33 -> 10.75 | F34: =G33+F33 -> 10.75 | H34: =I33+H33 -> 10.75
A35: WEEK | B35: 1 | D35: 2 | F35: 3 | H35: 4
A37: TOTAL Hours | B37: =SUM(B33:I33) -> 41.75
A38: VALUE per Hour | B38: 30
A39: Total | B39: =B37*B38 -> 1252.5

Sheet AUGUST  2025
A1: Day | B1: 45896
A2: Time | B2: Wednesday
A3: 13:00 - 13:15
A4: 13:15 - 13:30
A5: 13:30 - 13:45
A6: 13:45 - 14:00
A7: 14:00 - 14:15
A8: 14:15 - 14:30
A9: 14:30 - 14:45
A10: 14:45 - 15:00
A11: 15:00 - 15:15
A12: 15:15 - 15:30
A13: 15:30 - 15:45
A14: 15:45 - 16:00 | B14: U11B1
A15: 16:00 - 16:15 | B15: U11B1
A16: 16:15 - 16:30 | B16: U11B1
A17: 16:30 - 16:45 | B17: U11B1
A18: 16:45 - 17:00 | B18: U11B1
A19: 17:00 - 17:15 | B19: U11B1
A20: 17:15 - 17:30 | B20: U14B2
A21: 17:30 - 17:45 | B21: U14B2
A22: 17:45 - 18:00 | B22: U14B2
A23: 18:00 - 18:15 | B23: U14B2
A24: 18:15 - 18:30 | B24: U14B2
A25: 18:30 - 18:45 | B25: U14B2
A26: 18:45 - 19:00
A27: 19:00 - 19:15
A28: 19:15 - 19:30
A29: 19:30 - 19:45
A30: 19:45 - 20:00
A31: 20:00 - 20:15
A32: 20:15 - 20:30
A33: Hours per Day | B33: =(COUNTA(B3:B32))/4 -> 3
A34: Hours per Week | B34: =(COUNTA(B3:B32))/4 -> 3
A35: WEEK | B35: 4
A38: TOTAL Hours | B38: =SUM(B33:D33) -> 3
A39: Value per Hour | B39: 30
A40: Total | B40: =B38*B39 -> 90
